Workbook

Sheet General_Ledger_Data
A1: Txn_ID | B1: Posting_Date | C1: GL_Account | D1: Vendor_ID | E1: Quantity_Units | F1: Unit_Price_USD | G1: Raw_Extended_Cost | H1: Target_Subledger_Balance
A2: TXN-1001 | B2: 46023 | C2: 6001-OPEX | D2: VEND-801 | E2: 150 | F2: 45 | G2: 6750 | H2: 6750
A3: TXN-1002 | B3: 46023 | C3: 6002-CAPEX | D3: VEND-999 | E3: 80 | F3: #N/A | G3: #N/A | H3: 3200
A4: TXN-1003 | B4: 46024 | C4: 6001-OPEX | D4: VEND-803 | E4: 0 | F4: 120 | G4: #DIV/0! | H4: 0
A5: TXN-1004 | B5: 46024 | C5: 6003-SUPPLY | D5: VEND-804 | E5: 200 | F5: $15.50 | G5: 3100 | H5: 3100
A6: TXN-1005 | B6: 46025 | C6: 6001-OPEX | D6: VEND-805 | E6: 50 | F6: 310 | G6: 15500 | H6: 15500
A7: TXN-1006 | B7: 46025 | C7: 6004-TRAVEL | D7: VEND-806 | E7: INVALID_QTY | F7: 75 | G7: #VALUE! | H7: 1875
A8: TXN-1007 | B8: 46026 | C8: 6002-CAPEX | D8: VEND-807 | E8: 120 | F8: 95 | G8: 11400 | H8: 11400
A9: TXN-1008 | B9: 46026 | C9: 6003-SUPPLY | D9: VEND-808 | E9: 300 | F9: 0 | G9: #DIV/0! | H9: 0
A10: TXN-1009 | B10: 46027 | C10: 6001-OPEX | D10: VEND-999 | E10: 45 | F10: #N/A | G10: #N/A | H10: 1800
A11: TXN-1010 | B11: 46027 | C11: 6004-TRAVEL | D11: VEND-810 | E11: 500 | F11: 12.5 | G11: 6250 | H11: 6250
A12: TXN-1011 | B12: 46028 | C12: 6001-OPEX | D12: VEND-811 | E12: 75 | F12: 60 | G12: 4500 | H12: 4500
A13: TXN-1012 | B13: 46028 | C13: 6002-CAPEX | D13: VEND-812 | E13: 10 | F13: 1250 | G13: 12500 | H13: 12500.05
A14: TXN-1013 | B14: 46029 | C14: 6003-SUPPLY | D14: VEND-999 | E14: #N/A | F14: 45 | G14: #N/A | H14: 450
A15: TXN-1014 | B15: 46029 | C15: 6001-OPEX | D15: VEND-814 | E15: 220 | F15: $22.75 | G15: 5005 | H15: 5005
A16: TXN-1015 | B16: 46030 | C16: 6004-TRAVEL | D16: VEND-815 | E16: 15 | F16: 320 | G16: 4800 | H16: 4800
A17: TXN-1016 | B17: 46030 | C17: 6001-OPEX | D17: VEND-816 | E17: 90 | F17: ABC | G17: #VALUE! | H17: 2700
A18: TXN-1017 | B18: 46031 | C18: 6002-CAPEX | D18: VEND-817 | E18: 400 | F18: 18 | G18: 7200 | H18: 7200
A19: TXN-1018 | B19: 46031 | C19: 6003-SUPPLY | D19: VEND-818 | E19: 0 | F19: 55 | G19: #DIV/0! | H19: 0
A20: TXN-1019 | B20: 46032 | C20: 6001-OPEX | D20: VEND-999 | E20: 110 | F20: #N/A | G20: #N/A | H20: 3300
A21: TXN-1020 | B21: 46032 | C21: 6004-TRAVEL | D21: VEND-820 | E21: 60 | F21: 145 | G21: 8700 | H21: 8700
A22: TXN-1021 | B22: 46033 | C22: 6001-OPEX | D22: VEND-821 | E22: 300 | F22: 14 | G22: 4200 | H22: 4200
A23: TXN-1022 | B23: 46033 | C23: 6002-CAPEX | D23: VEND-822 | E23: 25 | F23: 450 | G23: 11250 | H23: 11250
A24: TXN-1023 | B24: 46034 | C24: 6003-SUPPLY | D24: VEND-823 | E24: 180 | F24: $35.00 | G24: 6300 | H24: 6300
A25: TXN-1024 | B25: 46034 | C25: 6001-OPEX | D25: VEND-824 | E25: ERR | F25: 90 | G25: #VALUE! | H25: 4500
A26: TXN-1025 | B26: 46035 | C26: 6004-TRAVEL | D26: VEND-825 | E26: 45 | F26: 210 | G26: 9450 | H26: 9450
A27: TXN-1026 | B27: 46035 | C27: 6001-OPEX | D27: VEND-999 | E27: 500 | F27: #N/A | G27: #N/A | H27: 10000
A28: TXN-1027 | B28: 46036 | C28: 6002-CAPEX | D28: VEND-827 | E28: 85 | F28: 180 | G28: 15300 | H28: 15300
A29: TXN-1028 | B29: 46036 | C29: 6003-SUPPLY | D29: VEND-828 | E29: 0 | F29: 85 | G29: #DIV/0! | H29: 0
A30: TXN-1029 | B30: 46037 | C30: 6001-OPEX | D30: VEND-829 | E30: 135 | F30: 50 | G30: 6750 | H30: 6750
A31: TXN-1030 | B31: 46037 | C31: 6004-TRAVEL | D31: VEND-830 | E31: 70 | F31: $110.00 | G31: 7700 | H31: 7700
A32: TXN-1031 | B32: 46038 | C32: 6001-OPEX | D32: VEND-831 | E32: 160 | F32: 42 | G32: 6720 | H32: 6720
A33: TXN-1032 | B33: 46038 | C33: 6002-CAPEX | D33: VEND-832 | E33: 95 | F33: 310 | G33: 29450 | H33: 29450
A34: TXN-1033 | B34: 46039 | C34: 6003-SUPPLY | D34: VEND-999 | E34: #N/A | F34: 15 | G34: #N/A | H34: 300
A35: TXN-1034 | B35: 46039 | C35: 6001-OPEX | D35: VEND-834 | E35: 210 | F35: 65 | G35: 13650 | H35: 13650
A36: TXN-1035 | B36: 46040 | C36: 6004-TRAVEL | D36: VEND-835 | E36: 30 | F36: 400 | G36: 12000 | H36: 12000
A37: TXN-1036 | B37: 46040 | C37: 6001-OPEX | D37: VEND-836 | E37: 115 | F37: N/A_PRICE | G37: #VALUE! | H37: 5750
A38: TXN-1037 | B38: 46041 | C38: 6002-CAPEX | D38: VEND-837 | E38: 350 | F38: 22 | G38: 7700 | H38: 7700
A39: TXN-1038 | B39: 46041 | C39: 6003-SUPPLY | D39: VEND-838 | E39: 0 | F39: 45 | G39: #DIV/0! | H39: 0
A40: TXN-1039 | B40: 46042 | C40: 6001-OPEX | D40: VEND-839 | E40: 85 | F40: 125 | G40: 10625 | H40: 10625
...

Sheet Formula_Repair_Engine
A1: Txn_ID | B1: Posting_Date | C1: GL_Account | D1: Vendor_ID | E1: Clean_Quantity | F1: Clean_Unit_Price | G1: Repaired_Extended_Cost | H1: Repair_Audit_Status
A2: =General_Ledger_Data!A2 -> TXN-1001 | B2: =General_Ledger_Data!B2 -> 46023 | C2: =General_Ledger_Data!C2 -> 6001-OPEX | D2: =IF(OR(ISBLANK(General_Ledger_Data!D2), General_Ledger_Data!D2="#N/A"), "VEND-UNKNOWN", General_Ledger_Data!D2) -> VEND-801 | E2: =IFERROR(__xludf.DUMMYFUNCTION("IFERROR(VALUE(REGEXREPLACE(TO_TEXT(General_Ledger_Data!E2), ""[^0-9.]"", """")), 0)"),150.0) -> 150 | F2: =IFERROR(__xludf.DUMMYFUNCTION("IFERROR(VALUE(REGEXREPLACE(TO_TEXT(General_Ledger_Data!F2), ""[^0-9.]"", """")), 0)"),45.0) -> 45 | G2: =IF(OR(E2=0, F2=0), 0, E2*F2) -> 6750 | H2: =IF(ISNUMBER(General_Ledger_Data!G2), "PASSED CLEAN", "REPAIRED") -> PASSED CLEAN
A3: =General_Ledger_Data!A3 -> TXN-1002 | B3: =General_Ledger_Data!B3 -> 46023 | C3: =General_Ledger_Data!C3 -> 6002-CAPEX | D3: =IF(OR(ISBLANK(General_Ledger_Data!D3), General_Ledger_Data!D3="#N/A"), "VEND-UNKNOWN", General_Ledger_Data!D3) -> VEND-999 | E3: =IFERROR(__xludf.DUMMYFUNCTION("IFERROR(VALUE(REGEXREPLACE(TO_TEXT(General_Ledger_Data!E3), ""[^0-9.]"", """")), 0)"),80.0) -> 80 | F3: =IFERROR(__xludf.DUMMYFUNCTION("IFERROR(VALUE(REGEXREPLACE(TO_TEXT(General_Ledger_Data!F3), ""[^0-9.]"", """")), 0)"),0.0) -> 0 | G3: =IF(OR(E3=0, F3=0), 0, E3*F3) -> 0 | H3: =IF(ISNUMBER(General_Ledger_Data!G3), "PASSED CLEAN", "REPAIRED") -> REPAIRED
A4: =General_Ledger_Data!A4 -> TXN-1003 | B4: =General_Ledger_Data!B4 -> 46024 | C4: =General_Ledger_Data!C4 -> 6001-OPEX | D4: =IF(OR(ISBLANK(General_Ledger_Data!D4), General_Ledger_Data!D4="#N/A"), "VEND-UNKNOWN", General_Ledger_Data!D4) -> VEND-803 | E4: =IFERROR(__xludf.DUMMYFUNCTION("IFERROR(VALUE(REGEXREPLACE(TO_TEXT(General_Ledger_Data!E4), ""[^0-9.]"", """")), 0)"),0.0) -> 0 | F4: =IFERROR(__xludf.DUMMYFUNCTION("IFERROR(VALUE(REGEXREPLACE(TO_TEXT(General_Ledger_Data!F4), ""[^0-9.]"", """")), 0)"),120.0) -> 120 | G4: =IF(OR(E4=0, F4=0), 0, E4*F4) -> 0 | H4: =IF(ISNUMBER(General_Ledger_Data!G4), "PASSED CLEAN", "REPAIRED") -> REPAIRED
A5: =General_Ledger_Data!A5 -> TXN-1004 | B5: =General_Ledger_Data!B5 -> 46024 | C5: =General_Ledger_Data!C5 -> 6003-SUPPLY | D5: =IF(OR(ISBLANK(General_Ledger_Data!D5), General_Ledger_Data!D5="#N/A"), "VEND-UNKNOWN", General_Ledger_Data!D5) -> VEND-804 | E5: =IFERROR(__xludf.DUMMYFUNCTION("IFERROR(VALUE(REGEXREPLACE(TO_TEXT(General_Ledger_Data!E5), ""[^0-9.]"", """")), 0)"),200.0) -> 200 | F5: =IFERROR(__xludf.DUMMYFUNCTION("IFERROR(VALUE(REGEXREPLACE(TO_TEXT(General_Ledger_Data!F5), ""[^0-9.]"", """")), 0)"),15.5) -> 15.5 | G5: =IF(OR(E5=0, F5=0), 0, E5*F5) -> 3100 | H5: =IF(ISNUMBER(General_Ledger_Data!G5), "PASSED CLEAN", "REPAIRED") -> PASSED CLEAN
A6: =General_Ledger_Data!A6 -> TXN-1005 | B6: =General_Ledger_Data!B6 -> 46025 | C6: =General_Ledger_Data!C6 -> 6001-OPEX | D6: =IF(OR(ISBLANK(General_Ledger_Data!D6), General_Ledger_Data!D6="#N/A"), "VEND-UNKNOWN", General_Ledger_Data!D6) -> VEND-805 | E6: =IFERROR(__xludf.DUMMYFUNCTION("IFERROR(VALUE(REGEXREPLACE(TO_TEXT(General_Ledger_Data!E6), ""[^0-9.]"", """")), 0)"),50.0) -> 50 | F6: =IFERROR(__xludf.DUMMYFUNCTION("IFERROR(VALUE(REGEXREPLACE(TO_TEXT(General_Ledger_Data!F6), ""[^0-9.]"", """")), 0)"),310.0) -> 310 | G6: =IF(OR(E6=0, F6=0), 0, E6*F6) -> 15500 | H6: =IF(ISNUMBER(General_Ledger_Data!G6), "PASSED CLEAN", "REPAIRED") -> PASSED CLEAN
A7: =General_Ledger_Data!A7 -> TXN-1006 | B7: =General_Ledger_Data!B7 -> 46025 | C7: =General_Ledger_Data!C7 -> 6004-TRAVEL | D7: =IF(OR(ISBLANK(General_Ledger_Data!D7), General_Ledger_Data!D7="#N/A"), "VEND-UNKNOWN", General_Ledger_Data!D7) -> VEND-806 | E7: =IFERROR(__xludf.DUMMYFUNCTION("IFERROR(VALUE(REGEXREPLACE(TO_TEXT(General_Ledger_Data!E7), ""[^0-9.]"", """")), 0)"),0.0) -> 0 | F7: =IFERROR(__xludf.DUMMYFUNCTION("IFERROR(VALUE(REGEXREPLACE(TO_TEXT(General_Ledger_Data!F7), ""[^0-9.]"", """")), 0)"),75.0) -> 75 | G7: =IF(OR(E7=0, F7=0), 0, E7*F7) -> 0 | H7: =IF(ISNUMBER(General_Ledger_Data!G7), "PASSED CLEAN", "REPAIRED") -> REPAIRED
A8: =General_Ledger_Data!A8 -> TXN-1007 | B8: =General_Ledger_Data!B8 -> 46026 | C8: =General_Ledger_Data!C8 -> 6002-CAPEX | D8: =IF(OR(ISBLANK(General_Ledger_Data!D8), General_Ledger_Data!D8="#N/A"), "VEND-UNKNOWN", General_Ledger_Data!D8) -> VEND-807 | E8: =IFERROR(__xludf.DUMMYFUNCTION("IFERROR(VALUE(REGEXREPLACE(TO_TEXT(General_Ledger_Data!E8), ""[^0-9.]"", """")), 0)"),120.0) -> 120 | F8: =IFERROR(__xludf.DUMMYFUNCTION("IFERROR(VALUE(REGEXREPLACE(TO_TEXT(General_Ledger_Data!F8), ""[^0-9.]"", """")), 0)"),95.0) -> 95 | G8: =IF(OR(E8=0, F8=0), 0, E8*F8) -> 11400 | H8: =IF(ISNUMBER(General_Ledger_Data!G8), "PASSED CLEAN", "REPAIRED") -> PASSED CLEAN
A9: =General_Ledger_Data!A9 -> TXN-1008 | B9: =General_Ledger_Data!B9 -> 46026 | C9: =General_Ledger_Data!C9 -> 6003-SUPPLY | D9: =IF(OR(ISBLANK(General_Ledger_Data!D9), General_Ledger_Data!D9="#N/A"), "VEND-UNKNOWN", General_Ledger_Data!D9) -> VEND-808 | E9: =IFERROR(__xludf.DUMMYFUNCTION("IFERROR(VALUE(REGEXREPLACE(TO_TEXT(General_Ledger_Data!E9), ""[^0-9.]"", """")), 0)"),300.0) -> 300 | F9: =IFERROR(__xludf.DUMMYFUNCTION("IFERROR(VALUE(REGEXREPLACE(TO_TEXT(General_Ledger_Data!F9), ""[^0-9.]"", """")), 0)"),0.0) -> 0 | G9: =IF(OR(E9=0, F9=0), 0, E9*F9) -> 0 | H9: =IF(ISNUMBER(General_Ledger_Data!G9), "PASSED CLEAN", "REPAIRED") -> REPAIRED
A10: =General_Ledger_Data!A10 -> TXN-1009 | B10: =General_Ledger_Data!B10 -> 46027 | C10: =General_Ledger_Data!C10 -> 6001-OPEX | D10: =IF(OR(ISBLANK(General_Ledger_Data!D10), General_Ledger_Data!D10="#N/A"), "VEND-UNKNOWN", General_Ledger_Data!D10) -> VEND-999 | E10: =IFERROR(__xludf.DUMMYFUNCTION("IFERROR(VALUE(REGEXREPLACE(TO_TEXT(General_Ledger_Data!E10), ""[^0-9.]"", """")), 0)"),45.0) -> 45 | F10: =IFERROR(__xludf.DUMMYFUNCTION("IFERROR(VALUE(REGEXREPLACE(TO_TEXT(General_Ledger_Data!F10), ""[^0-9.]"", """")), 0)"),0.0) -> 0 | G10: =IF(OR(E10=0, F10=0), 0, E10*F10) -> 0 | H10: =IF(ISNUMBER(General_Ledger_Data!G10), "PASSED CLEAN", "REPAIRED") -> REPAIRED
A11: =General_Ledger_Data!A11 -> TXN-1010 | B11: =General_Ledger_Data!B11 -> 46027 | C11: =General_Ledger_Data!C11 -> 6004-TRAVEL | D11: =IF(OR(ISBLANK(General_Ledger_Data!D11), General_Ledger_Data!D11="#N/A"), "VEND-UNKNOWN", General_Ledger_Data!D11) -> VEND-810 | E11: =IFERROR(__xludf.DUMMYFUNCTION("IFERROR(VALUE(REGEXREPLACE(TO_TEXT(General_Ledger_Data!E11), ""[^0-9.]"", """")), 0)"),500.0) -> 500 | F11: =IFERROR(__xludf.DUMMYFUNCTION("IFERROR(VALUE(REGEXREPLACE(TO_TEXT(General_Ledger_Data!F11), ""[^0-9.]"", """")), 0)"),12.5) -> 12.5 | G11: =IF(OR(E11=0, F11=0), 0, E11*F11) -> 6250 | H11: =IF(ISNUMBER(General_Ledger_Data!G11), "PASSED CLEAN", "REPAIRED") -> PASSED CLEAN
A12: =General_Ledger_Data!A12 -> TXN-1011 | B12: =General_Ledger_Data!B12 -> 46028 | C12: =General_Ledger_Data!C12 -> 6001-OPEX | D12: =IF(OR(ISBLANK(General_Ledger_Data!D12), General_Ledger_Data!D12="#N/A"), "VEND-UNKNOWN", General_Ledger_Data!D12) -> VEND-811 | E12: =IFERROR(__xludf.DUMMYFUNCTION("IFERROR(VALUE(REGEXREPLACE(TO_TEXT(General_Ledger_Data!E12), ""[^0-9.]"", """")), 0)"),75.0) -> 75 | F12: =IFERROR(__xludf.DUMMYFUNCTION("IFERROR(VALUE(REGEXREPLACE(TO_TEXT(General_Ledger_Data!F12), ""[^0-9.]"", """")), 0)"),60.0) -> 60 | G12: =IF(OR(E12=0, F12=0), 0, E12*F12) -> 4500 | H12: =IF(ISNUMBER(General_Ledger_Data!G12), "PASSED CLEAN", "REPAIRED") -> PASSED CLEAN
A13: =General_Ledger_Data!A13 -> TXN-1012 | B13: =General_Ledger_Data!B13 -> 46028 | C13: =General_Ledger_Data!C13 -> 6002-CAPEX | D13: =IF(OR(ISBLANK(General_Ledger_Data!D13), General_Ledger_Data!D13="#N/A"), "VEND-UNKNOWN", General_Ledger_Data!D13) -> VEND-812 | E13: =IFERROR(__xludf.DUMMYFUNCTION("IFERROR(VALUE(REGEXREPLACE(TO_TEXT(General_Ledger_Data!E13), ""[^0-9.]"", """")), 0)"),10.0) -> 10 | F13: =IFERROR(__xludf.DUMMYFUNCTION("IFERROR(VALUE(REGEXREPLACE(TO_TEXT(General_Ledger_Data!F13), ""[^0-9.]"", """")), 0)"),1250.0) -> 1250 | G13: =IF(OR(E13=0, F13=0), 0, E13*F13) -> 12500 | H13: =IF(ISNUMBER(General_Ledger_Data!G13), "PASSED CLEAN", "REPAIRED") -> PASSED CLEAN
A14: =General_Ledger_Data!A14 -> TXN-1013 | B14: =General_Ledger_Data!B14 -> 46029 | C14: =General_Ledger_Data!C14 -> 6003-SUPPLY | D14: =IF(OR(ISBLANK(General_Ledger_Data!D14), General_Ledger_Data!D14="#N/A"), "VEND-UNKNOWN", General_Ledger_Data!D14) -> VEND-999 | E14: =IFERROR(__xludf.DUMMYFUNCTION("IFERROR(VALUE(REGEXREPLACE(TO_TEXT(General_Ledger_Data!E14), ""[^0-9.]"", """")), 0)"),0.0) -> 0 | F14: =IFERROR(__xludf.DUMMYFUNCTION("IFERROR(VALUE(REGEXREPLACE(TO_TEXT(General_Ledger_Data!F14), ""[^0-9.]"", """")), 0)"),45.0) -> 45 | G14: =IF(OR(E14=0, F14=0), 0, E14*F14) -> 0 | H14: =IF(ISNUMBER(General_Ledger_Data!G14), "PASSED CLEAN", "REPAIRED") -> REPAIRED
A15: =General_Ledger_Data!A15 -> TXN-1014 | B15: =General_Ledger_Data!B15 -> 46029 | C15: =General_Ledger_Data!C15 -> 6001-OPEX | D15: =IF(OR(ISBLANK(General_Ledger_Data!D15), General_Ledger_Data!D15="#N/A"), "VEND-UNKNOWN", General_Ledger_Data!D15) -> VEND-814 | E15: =IFERROR(__xludf.DUMMYFUNCTION("IFERROR(VALUE(REGEXREPLACE(TO_TEXT(General_Ledger_Data!E15), ""[^0-9.]"", """")), 0)"),220.0) -> 220 | F15: =IFERROR(__xludf.DUMMYFUNCTION("IFERROR(VALUE(REGEXREPLACE(TO_TEXT(General_Ledger_Data!F15), ""[^0-9.]"", """")), 0)"),22.75) -> 22.75 | G15: =IF(OR(E15=0, F15=0), 0, E15*F15) -> 5005 | H15: =IF(ISNUMBER(General_Ledger_Data!G15), "PASSED CLEAN", "REPAIRED") -> PASSED CLEAN
A16: =General_Ledger_Data!A16 -> TXN-1015 | B16: =General_Ledger_Data!B16 -> 46030 | C16: =General_Ledger_Data!C16 -> 6004-TRAVEL | D16: =IF(OR(ISBLANK(General_Ledger_Data!D16), General_Ledger_Data!D16="#N/A"), "VEND-UNKNOWN", General_Ledger_Data!D16) -> VEND-815 | E16: =IFERROR(__xludf.DUMMYFUNCTION("IFERROR(VALUE(REGEXREPLACE(TO_TEXT(General_Ledger_Data!E16), ""[^0-9.]"", """")), 0)"),15.0) -> 15 | F16: =IFERROR(__xludf.DUMMYFUNCTION("IFERROR(VALUE(REGEXREPLACE(TO_TEXT(General_Ledger_Data!F16), ""[^0-9.]"", """")), 0)"),320.0) -> 320 | G16: =IF(OR(E16=0, F16=0), 0, E16*F16) -> 4800 | H16: =IF(ISNUMBER(General_Ledger_Data!G16), "PASSED CLEAN", "REPAIRED") -> PASSED CLEAN
A17: =General_Ledger_Data!A17 -> TXN-1016 | B17: =General_Ledger_Data!B17 -> 46030 | C17: =General_Ledger_Data!C17 -> 6001-OPEX | D17: =IF(OR(ISBLANK(General_Ledger_Data!D17), General_Ledger_Data!D17="#N/A"), "VEND-UNKNOWN", General_Ledger_Data!D17) -> VEND-816 | E17: =IFERROR(__xludf.DUMMYFUNCTION("IFERROR(VALUE(REGEXREPLACE(TO_TEXT(General_Ledger_Data!E17), ""[^0-9.]"", """")), 0)"),90.0) -> 90 | F17: =IFERROR(__xludf.DUMMYFUNCTION("IFERROR(VALUE(REGEXREPLACE(TO_TEXT(General_Ledger_Data!F17), ""[^0-9.]"", """")), 0)"),0.0) -> 0 | G17: =IF(OR(E17=0, F17=0), 0, E17*F17) -> 0 | H17: =IF(ISNUMBER(General_Ledger_Data!G17), "PASSED CLEAN", "REPAIRED") -> REPAIRED
A18: =General_Ledger_Data!A18 -> TXN-1017 | B18: =General_Ledger_Data!B18 -> 46031 | C18: =General_Ledger_Data!C18 -> 6002-CAPEX | D18: =IF(OR(ISBLANK(General_Ledger_Data!D18), General_Ledger_Data!D18="#N/A"), "VEND-UNKNOWN", General_Ledger_Data!D18) -> VEND-817 | E18: =IFERROR(__xludf.DUMMYFUNCTION("IFERROR(VALUE(REGEXREPLACE(TO_TEXT(General_Ledger_Data!E18), ""[^0-9.]"", """")), 0)"),400.0) -> 400 | F18: =IFERROR(__xludf.DUMMYFUNCTION("IFERROR(VALUE(REGEXREPLACE(TO_TEXT(General_Ledger_Data!F18), ""[^0-9.]"", """")), 0)"),18.0) -> 18 | G18: =IF(OR(E18=0, F18=0), 0, E18*F18) -> 7200 | H18: =IF(ISNUMBER(General_Ledger_Data!G18), "PASSED CLEAN", "REPAIRED") -> PASSED CLEAN
A19: =General_Ledger_Data!A19 -> TXN-1018 | B19: =General_Ledger_Data!B19 -> 46031 | C19: =General_Ledger_Data!C19 -> 6003-SUPPLY | D19: =IF(OR(ISBLANK(General_Ledger_Data!D19), General_Ledger_Data!D19="#N/A"), "VEND-UNKNOWN", General_Ledger_Data!D19) -> VEND-818 | E19: =IFERROR(__xludf.DUMMYFUNCTION("IFERROR(VALUE(REGEXREPLACE(TO_TEXT(General_Ledger_Data!E19), ""[^0-9.]"", """")), 0)"),0.0) -> 0 | F19: =IFERROR(__xludf.DUMMYFUNCTION("IFERROR(VALUE(REGEXREPLACE(TO_TEXT(General_Ledger_Data!F19), ""[^0-9.]"", """")), 0)"),55.0) -> 55 | G19: =IF(OR(E19=0, F19=0), 0, E19*F19) -> 0 | H19: =IF(ISNUMBER(General_Ledger_Data!G19), "PASSED CLEAN", "REPAIRED") -> REPAIRED
A20: =General_Ledger_Data!A20 -> TXN-1019 | B20: =General_Ledger_Data!B20 -> 46032 | C20: =General_Ledger_Data!C20 -> 6001-OPEX | D20: =IF(OR(ISBLANK(General_Ledger_Data!D20), General_Ledger_Data!D20="#N/A"), "VEND-UNKNOWN", General_Ledger_Data!D20) -> VEND-999 | E20: =IFERROR(__xludf.DUMMYFUNCTION("IFERROR(VALUE(REGEXREPLACE(TO_TEXT(General_Ledger_Data!E20), ""[^0-9.]"", """")), 0)"),110.0) -> 110 | F20: =IFERROR(__xludf.DUMMYFUNCTION("IFERROR(VALUE(REGEXREPLACE(TO_TEXT(General_Ledger_Data!F20), ""[^0-9.]"", """")), 0)"),0.0) -> 0 | G20: =IF(OR(E20=0, F20=0), 0, E20*F20) -> 0 | H20: =IF(ISNUMBER(General_Ledger_Data!G20), "PASSED CLEAN", "REPAIRED") -> REPAIRED
A21: =General_Ledger_Data!A21 -> TXN-1020 | B21: =General_Ledger_Data!B21 -> 46032 | C21: =General_Ledger_Data!C21 -> 6004-TRAVEL | D21: =IF(OR(ISBLANK(General_Ledger_Data!D21), General_Ledger_Data!D21="#N/A"), "VEND-UNKNOWN", General_Ledger_Data!D21) -> VEND-820 | E21: =IFERROR(__xludf.DUMMYFUNCTION("IFERROR(VALUE(REGEXREPLACE(TO_TEXT(General_Ledger_Data!E21), ""[^0-9.]"", """")), 0)"),60.0) -> 60 | F21: =IFERROR(__xludf.DUMMYFUNCTION("IFERROR(VALUE(REGEXREPLACE(TO_TEXT(General_Ledger_Data!F21), ""[^0-9.]"", """")), 0)"),145.0) -> 145 | G21: =IF(OR(E21=0, F21=0), 0, E21*F21) -> 8700 | H21: =IF(ISNUMBER(General_Ledger_Data!G21), "PASSED CLEAN", "REPAIRED") -> PASSED CLEAN
A22: =General_Ledger_Data!A22 -> TXN-1021 | B22: =General_Ledger_Data!B22 -> 46033 | C22: =General_Ledger_Data!C22 -> 6001-OPEX | D22: =IF(OR(ISBLANK(General_Ledger_Data!D22), General_Ledger_Data!D22="#N/A"), "VEND-UNKNOWN", General_Ledger_Data!D22) -> VEND-821 | E22: =IFERROR(__xludf.DUMMYFUNCTION("IFERROR(VALUE(REGEXREPLACE(TO_TEXT(General_Ledger_Data!E22), ""[^0-9.]"", """")), 0)"),300.0) -> 300 | F22: =IFERROR(__xludf.DUMMYFUNCTION("IFERROR(VALUE(REGEXREPLACE(TO_TEXT(General_Ledger_Data!F22), ""[^0-9.]"", """")), 0)"),14.0) -> 14 | G22: =IF(OR(E22=0, F22=0), 0, E22*F22) -> 4200 | H22: =IF(ISNUMBER(General_Ledger_Data!G22), "PASSED CLEAN", "REPAIRED") -> PASSED CLEAN
A23: =General_Ledger_Data!A23 -> TXN-1022 | B23: =General_Ledger_Data!B23 -> 46033 | C23: =General_Ledger_Data!C23 -> 6002-CAPEX | D23: =IF(OR(ISBLANK(General_Ledger_Data!D23), General_Ledger_Data!D23="#N/A"), "VEND-UNKNOWN", General_Ledger_Data!D23) -> VEND-822 | E23: =IFERROR(__xludf.DUMMYFUNCTION("IFERROR(VALUE(REGEXREPLACE(TO_TEXT(General_Ledger_Data!E23), ""[^0-9.]"", """")), 0)"),25.0) -> 25 | F23: =IFERROR(__xludf.DUMMYFUNCTION("IFERROR(VALUE(REGEXREPLACE(TO_TEXT(General_Ledger_Data!F23), ""[^0-9.]"", """")), 0)"),450.0) -> 450 | G23: =IF(OR(E23=0, F23=0), 0, E23*F23) -> 11250 | H23: =IF(ISNUMBER(General_Ledger_Data!G23), "PASSED CLEAN", "REPAIRED") -> PASSED CLEAN
A24: =General_Ledger_Data!A24 -> TXN-1023 | B24: =General_Ledger_Data!B24 -> 46034 | C24: =General_Ledger_Data!C24 -> 6003-SUPPLY | D24: =IF(OR(ISBLANK(General_Ledger_Data!D24), General_Ledger_Data!D24="#N/A"), "VEND-UNKNOWN", General_Ledger_Data!D24) -> VEND-823 | E24: =IFERROR(__xludf.DUMMYFUNCTION("IFERROR(VALUE(REGEXREPLACE(TO_TEXT(General_Ledger_Data!E24), ""[^0-9.]"", """")), 0)"),180.0) -> 180 | F24: =IFERROR(__xludf.DUMMYFUNCTION("IFERROR(VALUE(REGEXREPLACE(TO_TEXT(General_Ledger_Data!F24), ""[^0-9.]"", """")), 0)"),35.0) -> 35 | G24: =IF(OR(E24=0, F24=0), 0, E24*F24) -> 6300 | H24: =IF(ISNUMBER(General_Ledger_Data!G24), "PASSED CLEAN", "REPAIRED") -> PASSED CLEAN
A25: =General_Ledger_Data!A25 -> TXN-1024 | B25: =General_Ledger_Data!B25 -> 46034 | C25: =General_Ledger_Data!C25 -> 6001-OPEX | D25: =IF(OR(ISBLANK(General_Ledger_Data!D25), General_Ledger_Data!D25="#N/A"), "VEND-UNKNOWN", General_Ledger_Data!D25) -> VEND-824 | E25: =IFERROR(__xludf.DUMMYFUNCTION("IFERROR(VALUE(REGEXREPLACE(TO_TEXT(General_Ledger_Data!E25), ""[^0-9.]"", """")), 0)"),0.0) -> 0 | F25: =IFERROR(__xludf.DUMMYFUNCTION("IFERROR(VALUE(REGEXREPLACE(TO_TEXT(General_Ledger_Data!F25), ""[^0-9.]"", """")), 0)"),90.0) -> 90 | G25: =IF(OR(E25=0, F25=0), 0, E25*F25) -> 0 | H25: =IF(ISNUMBER(General_Ledger_Data!G25), "PASSED CLEAN", "REPAIRED") -> REPAIRED
A26: =General_Ledger_Data!A26 -> TXN-1025 | B26: =General_Ledger_Data!B26 -> 46035 | C26: =General_Ledger_Data!C26 -> 6004-TRAVEL | D26: =IF(OR(ISBLANK(General_Ledger_Data!D26), General_Ledger_Data!D26="#N/A"), "VEND-UNKNOWN", General_Ledger_Data!D26) -> VEND-825 | E26: =IFERROR(__xludf.DUMMYFUNCTION("IFERROR(VALUE(REGEXREPLACE(TO_TEXT(General_Ledger_Data!E26), ""[^0-9.]"", """")), 0)"),45.0) -> 45 | F26: =IFERROR(__xludf.DUMMYFUNCTION("IFERROR(VALUE(REGEXREPLACE(TO_TEXT(General_Ledger_Data!F26), ""[^0-9.]"", """")), 0)"),210.0) -> 210 | G26: =IF(OR(E26=0, F26=0), 0, E26*F26) -> 9450 | H26: =IF(ISNUMBER(General_Ledger_Data!G26), "PASSED CLEAN", "REPAIRED") -> PASSED CLEAN
A27: =General_Ledger_Data!A27 -> TXN-1026 | B27: =General_Ledger_Data!B27 -> 46035 | C27: =General_Ledger_Data!C27 -> 6001-OPEX | D27: =IF(OR(ISBLANK(General_Ledger_Data!D27), General_Ledger_Data!D27="#N/A"), "VEND-UNKNOWN", General_Ledger_Data!D27) -> VEND-999 | E27: =IFERROR(__xludf.DUMMYFUNCTION("IFERROR(VALUE(REGEXREPLACE(TO_TEXT(General_Ledger_Data!E27), ""[^0-9.]"", """")), 0)"),500.0) -> 500 | F27: =IFERROR(__xludf.DUMMYFUNCTION("IFERROR(VALUE(REGEXREPLACE(TO_TEXT(General_Ledger_Data!F27), ""[^0-9.]"", """")), 0)"),0.0) -> 0 | G27: =IF(OR(E27=0, F27=0), 0, E27*F27) -> 0 | H27: =IF(ISNUMBER(General_Ledger_Data!G27), "PASSED CLEAN", "REPAIRED") -> REPAIRED
A28: =General_Ledger_Data!A28 -> TXN-1027 | B28: =General_Ledger_Data!B28 -> 46036 | C28: =General_Ledger_Data!C28 -> 6002-CAPEX | D28: =IF(OR(ISBLANK(General_Ledger_Data!D28), General_Ledger_Data!D28="#N/A"), "VEND-UNKNOWN", General_Ledger_Data!D28) -> VEND-827 | E28: =IFERROR(__xludf.DUMMYFUNCTION("IFERROR(VALUE(REGEXREPLACE(TO_TEXT(General_Ledger_Data!E28), ""[^0-9.]"", """")), 0)"),85.0) -> 85 | F28: =IFERROR(__xludf.DUMMYFUNCTION("IFERROR(VALUE(REGEXREPLACE(TO_TEXT(General_Ledger_Data!F28), ""[^0-9.]"", """")), 0)"),180.0) -> 180 | G28: =IF(OR(E28=0, F28=0), 0, E28*F28) -> 15300 | H28: =IF(ISNUMBER(General_Ledger_Data!G28), "PASSED CLEAN", "REPAIRED") -> PASSED CLEAN
A29: =General_Ledger_Data!A29 -> TXN-1028 | B29: =General_Ledger_Data!B29 -> 46036 | C29: =General_Ledger_Data!C29 -> 6003-SUPPLY | D29: =IF(OR(ISBLANK(General_Ledger_Data!D29), General_Ledger_Data!D29="#N/A"), "VEND-UNKNOWN", General_Ledger_Data!D29) -> VEND-828 | E29: =IFERROR(__xludf.DUMMYFUNCTION("IFERROR(VALUE(REGEXREPLACE(TO_TEXT(General_Ledger_Data!E29), ""[^0-9.]"", """")), 0)"),0.0) -> 0 | F29: =IFERROR(__xludf.DUMMYFUNCTION("IFERROR(VALUE(REGEXREPLACE(TO_TEXT(General_Ledger_Data!F29), ""[^0-9.]"", """")), 0)"),85.0) -> 85 | G29: =IF(OR(E29=0, F29=0), 0, E29*F29) -> 0 | H29: =IF(ISNUMBER(General_Ledger_Data!G29), "PASSED CLEAN", "REPAIRED") -> REPAIRED
A30: =General_Ledger_Data!A30 -> TXN-1029 | B30: =General_Ledger_Data!B30 -> 46037 | C30: =General_Ledger_Data!C30 -> 6001-OPEX | D30: =IF(OR(ISBLANK(General_Ledger_Data!D30), General_Ledger_Data!D30="#N/A"), "VEND-UNKNOWN", General_Ledger_Data!D30) -> VEND-829 | E30: =IFERROR(__xludf.DUMMYFUNCTION("IFERROR(VALUE(REGEXREPLACE(TO_TEXT(General_Ledger_Data!E30), ""[^0-9.]"", """")), 0)"),135.0) -> 135 | F30: =IFERROR(__xludf.DUMMYFUNCTION("IFERROR(VALUE(REGEXREPLACE(TO_TEXT(General_Ledger_Data!F30), ""[^0-9.]"", """")), 0)"),50.0) -> 50 | G30: =IF(OR(E30=0, F30=0), 0, E30*F30) -> 6750 | H30: =IF(ISNUMBER(General_Ledger_Data!G30), "PASSED CLEAN", "REPAIRED") -> PASSED CLEAN
A31: =General_Ledger_Data!A31 -> TXN-1030 | B31: =General_Ledger_Data!B31 -> 46037 | C31: =General_Ledger_Data!C31 -> 6004-TRAVEL | D31: =IF(OR(ISBLANK(General_Ledger_Data!D31), General_Ledger_Data!D31="#N/A"), "VEND-UNKNOWN", General_Ledger_Data!D31) -> VEND-830 | E31: =IFERROR(__xludf.DUMMYFUNCTION("IFERROR(VALUE(REGEXREPLACE(TO_TEXT(General_Ledger_Data!E31), ""[^0-9.]"", """")), 0)"),70.0) -> 70 | F31: =IFERROR(__xludf.DUMMYFUNCTION("IFERROR(VALUE(REGEXREPLACE(TO_TEXT(General_Ledger_Data!F31), ""[^0-9.]"", """")), 0)"),110.0) -> 110 | G31: =IF(OR(E31=0, F31=0), 0, E31*F31) -> 7700 | H31: =IF(ISNUMBER(General_Ledger_Data!G31), "PASSED CLEAN", "REPAIRED") -> PASSED CLEAN
A32: =General_Ledger_Data!A32 -> TXN-1031 | B32: =General_Ledger_Data!B32 -> 46038 | C32: =General_Ledger_Data!C32 -> 6001-OPEX | D32: =IF(OR(ISBLANK(General_Ledger_Data!D32), General_Ledger_Data!D32="#N/A"), "VEND-UNKNOWN", General_Ledger_Data!D32) -> VEND-831 | E32: =IFERROR(__xludf.DUMMYFUNCTION("IFERROR(VALUE(REGEXREPLACE(TO_TEXT(General_Ledger_Data!E32), ""[^0-9.]"", """")), 0)"),160.0) -> 160 | F32: =IFERROR(__xludf.DUMMYFUNCTION("IFERROR(VALUE(REGEXREPLACE(TO_TEXT(General_Ledger_Data!F32), ""[^0-9.]"", """")), 0)"),42.0) -> 42 | G32: =IF(OR(E32=0, F32=0), 0, E32*F32) -> 6720 | H32: =IF(ISNUMBER(General_Ledger_Data!G32), "PASSED CLEAN", "REPAIRED") -> PASSED CLEAN
A33: =General_Ledger_Data!A33 -> TXN-1032 | B33: =General_Ledger_Data!B33 -> 46038 | C33: =General_Ledger_Data!C33 -> 6002-CAPEX | D33: =IF(OR(ISBLANK(General_Ledger_Data!D33), General_Ledger_Data!D33="#N/A"), "VEND-UNKNOWN", General_Ledger_Data!D33) -> VEND-832 | E33: =IFERROR(__xludf.DUMMYFUNCTION("IFERROR(VALUE(REGEXREPLACE(TO_TEXT(General_Ledger_Data!E33), ""[^0-9.]"", """")), 0)"),95.0) -> 95 | F33: =IFERROR(__xludf.DUMMYFUNCTION("IFERROR(VALUE(REGEXREPLACE(TO_TEXT(General_Ledger_Data!F33), ""[^0-9.]"", """")), 0)"),310.0) -> 310 | G33: =IF(OR(E33=0, F33=0), 0, E33*F33) -> 29450 | H33: =IF(ISNUMBER(General_Ledger_Data!G33), "PASSED CLEAN", "REPAIRED") -> PASSED CLEAN
A34: =General_Ledger_Data!A34 -> TXN-1033 | B34: =General_Ledger_Data!B34 -> 46039 | C34: =General_Ledger_Data!C34 -> 6003-SUPPLY | D34: =IF(OR(ISBLANK(General_Ledger_Data!D34), General_Ledger_Data!D34="#N/A"), "VEND-UNKNOWN", General_Ledger_Data!D34) -> VEND-999 | E34: =IFERROR(__xludf.DUMMYFUNCTION("IFERROR(VALUE(REGEXREPLACE(TO_TEXT(General_Ledger_Data!E34), ""[^0-9.]"", """")), 0)"),0.0) -> 0 | F34: =IFERROR(__xludf.DUMMYFUNCTION("IFERROR(VALUE(REGEXREPLACE(TO_TEXT(General_Ledger_Data!F34), ""[^0-9.]"", """")), 0)"),15.0) -> 15 | G34: =IF(OR(E34=0, F34=0), 0, E34*F34) -> 0 | H34: =IF(ISNUMBER(General_Ledger_Data!G34), "PASSED CLEAN", "REPAIRED") -> REPAIRED
A35: =General_Ledger_Data!A35 -> TXN-1034 | B35: =General_Ledger_Data!B35 -> 46039 | C35: =General_Ledger_Data!C35 -> 6001-OPEX | D35: =IF(OR(ISBLANK(General_Ledger_Data!D35), General_Ledger_Data!D35="#N/A"), "VEND-UNKNOWN", General_Ledger_Data!D35) -> VEND-834 | E35: =IFERROR(__xludf.DUMMYFUNCTION("IFERROR(VALUE(REGEXREPLACE(TO_TEXT(General_Ledger_Data!E35), ""[^0-9.]"", """")), 0)"),210.0) -> 210 | F35: =IFERROR(__xludf.DUMMYFUNCTION("IFERROR(VALUE(REGEXREPLACE(TO_TEXT(General_Ledger_Data!F35), ""[^0-9.]"", """")), 0)"),65.0) -> 65 | G35: =IF(OR(E35=0, F35=0), 0, E35*F35) -> 13650 | H35: =IF(ISNUMBER(General_Ledger_Data!G35), "PASSED CLEAN", "REPAIRED") -> PASSED CLEAN
A36: =General_Ledger_Data!A36 -> TXN-1035 | B36: =General_Ledger_Data!B36 -> 46040 | C36: =General_Ledger_Data!C36 -> 6004-TRAVEL | D36: =IF(OR(ISBLANK(General_Ledger_Data!D36), General_Ledger_Data!D36="#N/A"), "VEND-UNKNOWN", General_Ledger_Data!D36) -> VEND-835 | E36: =IFERROR(__xludf.DUMMYFUNCTION("IFERROR(VALUE(REGEXREPLACE(TO_TEXT(General_Ledger_Data!E36), ""[^0-9.]"", """")), 0)"),30.0) -> 30 | F36: =IFERROR(__xludf.DUMMYFUNCTION("IFERROR(VALUE(REGEXREPLACE(TO_TEXT(General_Ledger_Data!F36), ""[^0-9.]"", """")), 0)"),400.0) -> 400 | G36: =IF(OR(E36=0, F36=0), 0, E36*F36) -> 12000 | H36: =IF(ISNUMBER(General_Ledger_Data!G36), "PASSED CLEAN", "REPAIRED") -> PASSED CLEAN
A37: =General_Ledger_Data!A37 -> TXN-1036 | B37: =General_Ledger_Data!B37 -> 46040 | C37: =General_Ledger_Data!C37 -> 6001-OPEX | D37: =IF(OR(ISBLANK(General_Ledger_Data!D37), General_Ledger_Data!D37="#N/A"), "VEND-UNKNOWN", General_Ledger_Data!D37) -> VEND-836 | E37: =IFERROR(__xludf.DUMMYFUNCTION("IFERROR(VALUE(REGEXREPLACE(TO_TEXT(General_Ledger_Data!E37), ""[^0-9.]"", """")), 0)"),115.0) -> 115 | F37: =IFERROR(__xludf.DUMMYFUNCTION("IFERROR(VALUE(REGEXREPLACE(TO_TEXT(General_Ledger_Data!F37), ""[^0-9.]"", """")), 0)"),0.0) -> 0 | G37: =IF(OR(E37=0, F37=0), 0, E37*F37) -> 0 | H37: =IF(ISNUMBER(General_Ledger_Data!G37), "PASSED CLEAN", "REPAIRED") -> REPAIRED
A38: =General_Ledger_Data!A38 -> TXN-1037 | B38: =General_Ledger_Data!B38 -> 46041 | C38: =General_Ledger_Data!C38 -> 6002-CAPEX | D38: =IF(OR(ISBLANK(General_Ledger_Data!D38), General_Ledger_Data!D38="#N/A"), "VEND-UNKNOWN", General_Ledger_Data!D38) -> VEND-837 | E38: =IFERROR(__xludf.DUMMYFUNCTION("IFERROR(VALUE(REGEXREPLACE(TO_TEXT(General_Ledger_Data!E38), ""[^0-9.]"", """")), 0)"),350.0) -> 350 | F38: =IFERROR(__xludf.DUMMYFUNCTION("IFERROR(VALUE(REGEXREPLACE(TO_TEXT(General_Ledger_Data!F38), ""[^0-9.]"", """")), 0)"),22.0) -> 22 | G38: =IF(OR(E38=0, F38=0), 0, E38*F38) -> 7700 | H38: =IF(ISNUMBER(General_Ledger_Data!G38), "PASSED CLEAN", "REPAIRED") -> PASSED CLEAN
A39: =General_Ledger_Data!A39 -> TXN-1038 | B39: =General_Ledger_Data!B39 -> 46041 | C39: =General_Ledger_Data!C39 -> 6003-SUPPLY | D39: =IF(OR(ISBLANK(General_Ledger_Data!D39), General_Ledger_Data!D39="#N/A"), "VEND-UNKNOWN", General_Ledger_Data!D39) -> VEND-838 | E39: =IFERROR(__xludf.DUMMYFUNCTION("IFERROR(VALUE(REGEXREPLACE(TO_TEXT(General_Ledger_Data!E39), ""[^0-9.]"", """")), 0)"),0.0) -> 0 | F39: =IFERROR(__xludf.DUMMYFUNCTION("IFERROR(VALUE(REGEXREPLACE(TO_TEXT(General_Ledger_Data!F39), ""[^0-9.]"", """")), 0)"),45.0) -> 45 | G39: =IF(OR(E39=0, F39=0), 0, E39*F39) -> 0 | H39: =IF(ISNUMBER(General_Ledger_Data!G39), "PASSED CLEAN", "REPAIRED") -> REPAIRED
A40: =General_Ledger_Data!A40 -> TXN-1039 | B40: =General_Ledger_Data!B40 -> 46042 | C40: =General_Ledger_Data!C40 -> 6001-OPEX | D40: =IF(OR(ISBLANK(General_Ledger_Data!D40), General_Ledger_Data!D40="#N/A"), "VEND-UNKNOWN", General_Ledger_Data!D40) -> VEND-839 | E40: =IFERROR(__xludf.DUMMYFUNCTION("IFERROR(VALUE(REGEXREPLACE(TO_TEXT(General_Ledger_Data!E40), ""[^0-9.]"", """")), 0)"),85.0) -> 85 | F40: =IFERROR(__xludf.DUMMYFUNCTION("IFERROR(VALUE(REGEXREPLACE(TO_TEXT(General_Ledger_Data!F40), ""[^0-9.]"", """")), 0)"),125.0) -> 125 | G40: =IF(OR(E40=0, F40=0), 0, E40*F40) -> 10625 | H40: =IF(ISNUMBER(General_Ledger_Data!G40), "PASSED CLEAN", "REPAIRED") -> PASSED CLEAN
...

Sheet Reconciliation_Matrix
A1: Txn_ID | B1: Repaired_Cost | C1: Subledger_Balance | D1: Absolute_Variance | E1: Tolerance_Threshold | F1: Reconciliation_Status
A2: =General_Ledger_Data!A2 -> TXN-1001 | B2: =Formula_Repair_Engine!G2 -> 6750 | C2: =General_Ledger_Data!H2 -> 6750 | D2: =ABS(B2-C2) -> 0 | E2: =0.04 -> 0.04 | F2: =IF(D2<=E2, "MATCHED", "VARIANCE DETECTED") -> MATCHED
A3: =General_Ledger_Data!A3 -> TXN-1002 | B3: =Formula_Repair_Engine!G3 -> 0 | C3: =General_Ledger_Data!H3 -> 3200 | D3: =ABS(B3-C3) -> 3200 | E3: =0.04 -> 0.04 | F3: =IF(D3<=E3, "MATCHED", "VARIANCE DETECTED") -> VARIANCE DETECTED
A4: =General_Ledger_Data!A4 -> TXN-1003 | B4: =Formula_Repair_Engine!G4 -> 0 | C4: =General_Ledger_Data!H4 -> 0 | D4: =ABS(B4-C4) -> 0 | E4: =0.04 -> 0.04 | F4: =IF(D4<=E4, "MATCHED", "VARIANCE DETECTED") -> MATCHED
A5: =General_Ledger_Data!A5 -> TXN-1004 | B5: =Formula_Repair_Engine!G5 -> 3100 | C5: =General_Ledger_Data!H5 -> 3100 | D5: =ABS(B5-C5) -> 0 | E5: =0.04 -> 0.04 | F5: =IF(D5<=E5, "MATCHED", "VARIANCE DETECTED") -> MATCHED
A6: =General_Ledger_Data!A6 -> TXN-1005 | B6: =Formula_Repair_Engine!G6 -> 15500 | C6: =General_Ledger_Data!H6 -> 15500 | D6: =ABS(B6-C6) -> 0 | E6: =0.04 -> 0.04 | F6: =IF(D6<=E6, "MATCHED", "VARIANCE DETECTED") -> MATCHED
A7: =General_Ledger_Data!A7 -> TXN-1006 | B7: =Formula_Repair_Engine!G7 -> 0 | C7: =General_Ledger_Data!H7 -> 1875 | D7: =ABS(B7-C7) -> 1875 | E7: =0.04 -> 0.04 | F7: =IF(D7<=E7, "MATCHED", "VARIANCE DETECTED") -> VARIANCE DETECTED
A8: =General_Ledger_Data!A8 -> TXN-1007 | B8: =Formula_Repair_Engine!G8 -> 11400 | C8: =General_Ledger_Data!H8 -> 11400 | D8: =ABS(B8-C8) -> 0 | E8: =0.04 -> 0.04 | F8: =IF(D8<=E8, "MATCHED", "VARIANCE DETECTED") -> MATCHED
A9: =General_Ledger_Data!A9 -> TXN-1008 | B9: =Formula_Repair_Engine!G9 -> 0 | C9: =General_Ledger_Data!H9 -> 0 | D9: =ABS(B9-C9) -> 0 | E9: =0.04 -> 0.04 | F9: =IF(D9<=E9, "MATCHED", "VARIANCE DETECTED") -> MATCHED
A10: =General_Ledger_Data!A10 -> TXN-1009 | B10: =Formula_Repair_Engine!G10 -> 0 | C10: =General_Ledger_Data!H10 -> 1800 | D10: =ABS(B10-C10) -> 1800 | E10: =0.04 -> 0.04 | F10: =IF(D10<=E10, "MATCHED", "VARIANCE DETECTED") -> VARIANCE DETECTED
A11: =General_Ledger_Data!A11 -> TXN-1010 | B11: =Formula_Repair_Engine!G11 -> 6250 | C11: =General_Ledger_Data!H11 -> 6250 | D11: =ABS(B11-C11) -> 0 | E11: =0.04 -> 0.04 | F11: =IF(D11<=E11, "MATCHED", "VARIANCE DETECTED") -> MATCHED
A12: =General_Ledger_Data!A12 -> TXN-1011 | B12: =Formula_Repair_Engine!G12 -> 4500 | C12: =General_Ledger_Data!H12 -> 4500 | D12: =ABS(B12-C12) -> 0 | E12: =0.04 -> 0.04 | F12: =IF(D12<=E12, "MATCHED", "VARIANCE DETECTED") -> MATCHED
A13: =General_Ledger_Data!A13 -> TXN-1012 | B13: =Formula_Repair_Engine!G13 -> 12500 | C13: =General_Ledger_Data!H13 -> 12500.05 | D13: =ABS(B13-C13) -> 0.05 | E13: =0.04 -> 0.04 | F13: =IF(D13<=E13, "MATCHED", "VARIANCE DETECTED") -> VARIANCE DETECTED
... A101: =General_Ledger_Data!A101 -> TXN-1100 | B101: =Formula_Repair_Engine!G101 -> 4500 | C101: =General_Ledger_Data!H101 -> 4500 | D101: =ABS(B101-C101) -> 0 | E101: =0.04 -> 0.04 | F101: =IF(D101<=E101, "MATCHED", "VARIANCE DETECTED") -> MATCHED

Sheet Executive_Dashboard
A1: ENTERPRISE FINANCIAL AUDIT & REPAIR EXECUTIVE CONSOLE
A3: Total Transactions Audited | B3: Errors Trapped & Repaired | C3: Reconciliation Variances | D3: System Health Stability Score
A4: =COUNTA(General_Ledger_Data!A2:A101) -> 100 | B4: =COUNTIF(Formula_Repair_Engine!H2:H101, "REPAIRED") -> 34 | C4: =COUNTIF(Reconciliation_Matrix!F2:F101, "VARIANCE DETECTED") -> 27 | D4: =(1 - (B4 / A4)) -> 0.66
